[2018-03-31 00:54:38 -0300] [4519] [INFO] Starting gunicorn 19.7.1
[2018-03-31 00:54:38 -0300] [4519] [INFO] Listening at: http://127.0.0.1:8000 (4519)
[2018-03-31 00:54:38 -0300] [4519] [INFO] Using worker: sync
[2018-03-31 00:54:38 -0300] [4522] [INFO] Booting worker with pid: 4522
mongod --help for help and startup options
2018-03-31T00:55:15.435-0300 [initandlisten] MongoDB starting : pid=4530 port=27017 dbpath=/data/db 64-bit host=laws04
2018-03-31T00:55:15.435-0300 [initandlisten] db version v2.6.10
2018-03-31T00:55:15.435-0300 [initandlisten] git version: nogitversion
2018-03-31T00:55:15.435-0300 [initandlisten] OpenSSL version: OpenSSL 1.0.2g  1 Mar 2016
2018-03-31T00:55:15.435-0300 [initandlisten] build info: Linux lgw01-12 3.19.0-25-generic #26~14.04.1-Ubuntu SMP Fri Jul 24 21:16:20 UTC 2015 x86_64 BOOST_LIB_VERSION=1_58
2018-03-31T00:55:15.435-0300 [initandlisten] allocator: tcmalloc
2018-03-31T00:55:15.435-0300 [initandlisten] options: {}
2018-03-31T00:55:15.439-0300 [initandlisten] journal dir=/data/db/journal
2018-03-31T00:55:15.439-0300 [initandlisten] recover : no journal files present, no recovery needed
2018-03-31T00:55:16.000-0300 [initandlisten] preallocateIsFaster=true 2.98
2018-03-31T00:55:17.003-0300 [initandlisten] preallocateIsFaster=true 18.4
2018-03-31T00:55:18.127-0300 [initandlisten] waiting for connections on port 27017
2018-03-31T00:55:19.042-0300 [initandlisten] connection accepted from 127.0.0.1:53834 #1 (1 connection now open)
2018-03-31T00:56:18.129-0300 [clientcursormon] mem (MB) res:58 virt:540
2018-03-31T00:56:18.129-0300 [clientcursormon]  mapped (incl journal view):320
2018-03-31T00:56:18.129-0300 [clientcursormon]  connections:1
2018-03-31T00:56:33.121-0300 [signalProcessingThread] got signal 1 (Hangup), will terminate after current cmd ends
2018-03-31T00:56:33.121-0300 [signalProcessingThread] now exiting
2018-03-31T00:56:33.121-0300 [signalProcessingThread] dbexit: 
2018-03-31T00:56:33.121-0300 [signalProcessingThread] shutdown: going to close listening sockets...
2018-03-31T00:56:33.121-0300 [signalProcessingThread] closing listening socket: 7
2018-03-31T00:56:33.121-0300 [signalProcessingThread] closing listening socket: 9
2018-03-31T00:56:33.121-0300 [signalProcessingThread] removing socket file: /tmp/mongodb-27017.sock
2018-03-31T00:56:33.121-0300 [signalProcessingThread] shutdown: going to flush diaglog...
2018-03-31T00:56:33.121-0300 [signalProcessingThread] shutdown: going to close sockets...
2018-03-31T00:56:33.121-0300 [signalProcessingThread] shutdown: waiting for fs preallocator...
2018-03-31T00:56:33.121-0300 [signalProcessingThread] shutdown: lock for final commit...
2018-03-31T00:56:33.121-0300 [signalProcessingThread] shutdown: final commit...
2018-03-31T00:56:33.121-0300 [signalProcessingThread] shutdown: closing all files...
2018-03-31T00:56:33.121-0300 [conn1] end connection 127.0.0.1:53834 (0 connections now open)
2018-03-31T00:56:33.122-0300 [signalProcessingThread] closeAllFiles() finished
2018-03-31T00:56:33.122-0300 [signalProcessingThread] journalCleanup...
2018-03-31T00:56:33.122-0300 [signalProcessingThread] removeJournalFiles
2018-03-31T00:56:33.126-0300 [signalProcessingThread] shutdown: removing fs lock...
2018-03-31T00:56:33.126-0300 [signalProcessingThread] dbexit: really exiting now
[2018-03-31 00:56:35 -0300] [4519] [INFO] Handling signal: hup
[2018-03-31 00:56:35 -0300] [4519] [INFO] Hang up: Master
[2018-03-31 00:56:35 -0300] [4551] [INFO] Booting worker with pid: 4551
[2018-03-31 00:57:15,253] ERROR in app: Exception on /classroom/ [GET]
Traceback (most recent call last):
  File "/home/laws/classroom/venv/lib/python3.5/site-packages/flask/app.py", line 1982, in wsgi_app
    response = self.full_dispatch_request()
  File "/home/laws/classroom/venv/lib/python3.5/site-packages/flask/app.py", line 1614, in full_dispatch_request
    rv = self.handle_user_exception(e)
  File "/home/laws/classroom/venv/lib/python3.5/site-packages/flask/app.py", line 1517, in handle_user_exception
    reraise(exc_type, exc_value, tb)
  File "/home/laws/classroom/venv/lib/python3.5/site-packages/flask/_compat.py", line 33, in reraise
    raise value
  File "/home/laws/classroom/venv/lib/python3.5/site-packages/flask/app.py", line 1612, in full_dispatch_request
    rv = self.dispatch_request()
  File "/home/laws/classroom/venv/lib/python3.5/site-packages/flask/app.py", line 1598, in dispatch_request
    return self.view_functions[rule.endpoint](**req.view_args)
  File "/home/laws/classroom/classroom/controllers/routes.py", line 16, in index
    return render_template("index.html", classes=classes, my_classes=my_classes, user=session["_id"])
  File "/home/laws/classroom/venv/lib/python3.5/site-packages/flask/templating.py", line 134, in render_template
    context, ctx.app)
  File "/home/laws/classroom/venv/lib/python3.5/site-packages/flask/templating.py", line 116, in _render
    rv = template.render(context)
  File "/home/laws/classroom/venv/lib/python3.5/site-packages/jinja2/environment.py", line 1008, in render
    return self.environment.handle_exception(exc_info, True)
  File "/home/laws/classroom/venv/lib/python3.5/site-packages/jinja2/environment.py", line 780, in handle_exception
    reraise(exc_type, exc_value, tb)
  File "/home/laws/classroom/venv/lib/python3.5/site-packages/jinja2/_compat.py", line 37, in reraise
    raise value.with_traceback(tb)
  File "/home/laws/classroom/classroom/templates/index.html", line 34, in top-level template code
    {% for class in classes %}
  File "/home/laws/classroom/venv/lib/python3.5/site-packages/pymongo/cursor.py", line 1169, in next
    if len(self.__data) or self._refresh():
  File "/home/laws/classroom/venv/lib/python3.5/site-packages/pymongo/cursor.py", line 1068, in _refresh
    self.__session = self.__collection.database.client._ensure_session()
  File "/home/laws/classroom/venv/lib/python3.5/site-packages/pymongo/mongo_client.py", line 1394, in _ensure_session
    return self.start_session(causal_consistency=False)
  File "/home/laws/classroom/venv/lib/python3.5/site-packages/pymongo/mongo_client.py", line 1372, in start_session
    server_session = self._get_server_session()
  File "/home/laws/classroom/venv/lib/python3.5/site-packages/pymongo/mongo_client.py", line 1380, in _get_server_session
    return self._topology.get_server_session()
  File "/home/laws/classroom/venv/lib/python3.5/site-packages/pymongo/topology.py", line 427, in get_server_session
    None)
  File "/home/laws/classroom/venv/lib/python3.5/site-packages/pymongo/topology.py", line 199, in _select_servers_loop
    self._error_message(selector))
pymongo.errors.ServerSelectionTimeoutError: localhost:27017: [Errno 111] Connection refused
[2018-03-31 00:59:42,522] ERROR in app: Exception on /classroom/ [GET]
Traceback (most recent call last):
  File "/home/laws/classroom/venv/lib/python3.5/site-packages/flask/app.py", line 1982, in wsgi_app
    response = self.full_dispatch_request()
  File "/home/laws/classroom/venv/lib/python3.5/site-packages/flask/app.py", line 1614, in full_dispatch_request
    rv = self.handle_user_exception(e)
  File "/home/laws/classroom/venv/lib/python3.5/site-packages/flask/app.py", line 1517, in handle_user_exception
    reraise(exc_type, exc_value, tb)
  File "/home/laws/classroom/venv/lib/python3.5/site-packages/flask/_compat.py", line 33, in reraise
    raise value
  File "/home/laws/classroom/venv/lib/python3.5/site-packages/flask/app.py", line 1612, in full_dispatch_request
    rv = self.dispatch_request()
  File "/home/laws/classroom/venv/lib/python3.5/site-packages/flask/app.py", line 1598, in dispatch_request
    return self.view_functions[rule.endpoint](**req.view_args)
  File "/home/laws/classroom/classroom/controllers/routes.py", line 16, in index
    return render_template("index.html", classes=classes, my_classes=my_classes, user=session["_id"])
  File "/home/laws/classroom/venv/lib/python3.5/site-packages/flask/templating.py", line 134, in render_template
    context, ctx.app)
  File "/home/laws/classroom/venv/lib/python3.5/site-packages/flask/templating.py", line 116, in _render
    rv = template.render(context)
  File "/home/laws/classroom/venv/lib/python3.5/site-packages/jinja2/environment.py", line 1008, in render
    return self.environment.handle_exception(exc_info, True)
  File "/home/laws/classroom/venv/lib/python3.5/site-packages/jinja2/environment.py", line 780, in handle_exception
    reraise(exc_type, exc_value, tb)
  File "/home/laws/classroom/venv/lib/python3.5/site-packages/jinja2/_compat.py", line 37, in reraise
    raise value.with_traceback(tb)
  File "/home/laws/classroom/classroom/templates/index.html", line 34, in top-level template code
    {% for class in classes %}
  File "/home/laws/classroom/venv/lib/python3.5/site-packages/pymongo/cursor.py", line 1169, in next
    if len(self.__data) or self._refresh():
  File "/home/laws/classroom/venv/lib/python3.5/site-packages/pymongo/cursor.py", line 1068, in _refresh
    self.__session = self.__collection.database.client._ensure_session()
  File "/home/laws/classroom/venv/lib/python3.5/site-packages/pymongo/mongo_client.py", line 1394, in _ensure_session
    return self.start_session(causal_consistency=False)
  File "/home/laws/classroom/venv/lib/python3.5/site-packages/pymongo/mongo_client.py", line 1372, in start_session
    server_session = self._get_server_session()
  File "/home/laws/classroom/venv/lib/python3.5/site-packages/pymongo/mongo_client.py", line 1380, in _get_server_session
    return self._topology.get_server_session()
  File "/home/laws/classroom/venv/lib/python3.5/site-packages/pymongo/topology.py", line 427, in get_server_session
    None)
  File "/home/laws/classroom/venv/lib/python3.5/site-packages/pymongo/topology.py", line 199, in _select_servers_loop
    self._error_message(selector))
pymongo.errors.ServerSelectionTimeoutError: localhost:27017: [Errno 111] Connection refused
[2018-03-31 14:37:26,505] ERROR in app: Exception on /classroom/login/ [POST]
Traceback (most recent call last):
  File "/home/laws/classroom/venv/lib/python3.5/site-packages/flask/app.py", line 1982, in wsgi_app
    response = self.full_dispatch_request()
  File "/home/laws/classroom/venv/lib/python3.5/site-packages/flask/app.py", line 1614, in full_dispatch_request
    rv = self.handle_user_exception(e)
  File "/home/laws/classroom/venv/lib/python3.5/site-packages/flask/app.py", line 1517, in handle_user_exception
    reraise(exc_type, exc_value, tb)
  File "/home/laws/classroom/venv/lib/python3.5/site-packages/flask/_compat.py", line 33, in reraise
    raise value
  File "/home/laws/classroom/venv/lib/python3.5/site-packages/flask/app.py", line 1612, in full_dispatch_request
    rv = self.dispatch_request()
  File "/home/laws/classroom/venv/lib/python3.5/site-packages/flask/app.py", line 1598, in dispatch_request
    return self.view_functions[rule.endpoint](**req.view_args)
  File "/home/laws/classroom/classroom/controllers/UserController.py", line 22, in login
    user = db.users.find_one( {"email": email} )
  File "/home/laws/classroom/venv/lib/python3.5/site-packages/pymongo/collection.py", line 1225, in find_one
    for result in cursor.limit(-1):
  File "/home/laws/classroom/venv/lib/python3.5/site-packages/pymongo/cursor.py", line 1169, in next
    if len(self.__data) or self._refresh():
  File "/home/laws/classroom/venv/lib/python3.5/site-packages/pymongo/cursor.py", line 1068, in _refresh
    self.__session = self.__collection.database.client._ensure_session()
  File "/home/laws/classroom/venv/lib/python3.5/site-packages/pymongo/mongo_client.py", line 1394, in _ensure_session
    return self.start_session(causal_consistency=False)
  File "/home/laws/classroom/venv/lib/python3.5/site-packages/pymongo/mongo_client.py", line 1372, in start_session
    server_session = self._get_server_session()
  File "/home/laws/classroom/venv/lib/python3.5/site-packages/pymongo/mongo_client.py", line 1380, in _get_server_session
    return self._topology.get_server_session()
  File "/home/laws/classroom/venv/lib/python3.5/site-packages/pymongo/topology.py", line 427, in get_server_session
    None)
  File "/home/laws/classroom/venv/lib/python3.5/site-packages/pymongo/topology.py", line 199, in _select_servers_loop
    self._error_message(selector))
pymongo.errors.ServerSelectionTimeoutError: localhost:27017: [Errno 111] Connection refused
[2018-03-31 19:50:34 -0300] [4519] [INFO] Handling signal: hup
[2018-03-31 19:50:34 -0300] [4519] [INFO] Hang up: Master
[2018-03-31 19:50:34 -0300] [4519] [INFO] Handling signal: term
[2018-03-31 19:50:34 -0300] [19012] [INFO] Booting worker with pid: 19012
[2018-03-31 19:51:04 -0300] [4519] [INFO] Shutting down: Master
